<?xml version="1.0" encoding="utf-8"?>
<mujoco>
	<compiler angle="radian" coordinate="local" meshdir="../stls/fetch" texturedir="../textures"></compiler>

    <asset>
        <mesh file="../switch/lightswitch.stl" name="lightswitch"/>
        <mesh file="../switch/lightswitchbase.stl" name="lightswitchbase"/>
    </asset>

	<option timestep="0.002">
		<flag warmstart="enable"></flag>
	</option>

	<include file="shared.xml"></include>
	
	<worldbody>
		<geom name="floor0" pos="0.8 0.75 0" size="0.85 0.70 1" type="plane" condim="3" material="floor_mat"></geom>
		<body name="floor0" pos="0.8 0.75 0">
			<site name="target0" pos="0 0 0.5" size="0.02 0.02 0.02" rgba="1 0 0 1" type="sphere"></site>
			<site name="target1" pos="0 0 0.5" size="0.02 0.02 0.02" rgba="0 1 0 1" type="sphere"></site>
			<site name="target2" pos="0 0 0.5" size="0.02 0.02 0.02" rgba="0 0 1 1" type="sphere"></site>
		</body>

        <body name="lightswitchbase0" pos="0.0 0.0 0.41">
			<site name="lightswitchbase0" pos="0 0 0" size="0.01 0.01 0.01" rgba="1 0 0 1" type="sphere"></site>
            <geom mesh="lightswitchbase" pos="0 0 0" euler="0 0 0" condim="3" contype="0"/>
            <body name="lightswitchroot0">
                <inertial pos="0 0 0" mass=".1" diaginertia="0.001 0.001 0.001"/>
                <joint axis="1 0 0" limited="true" name="lightswitchroot0:joint" frictionloss="1" range="-.7 .7"/>
                <geom pos="0 0 0.06" euler="0 0 0" size="0.02 0.035" type="capsule" condim="3" contype="0"/>
            </body>
        </body>

        <body name="lightswitchbase1" pos="0.0 0.0 0.41">
			<site name="lightswitchbase1" pos="0 0 0" size="0.01 0.01 0.01" rgba="1 0 0 1" type="sphere"></site>
            <geom mesh="lightswitchbase" pos="0 0 0" euler="0 0 0" condim="3" contype="0"/>
            <body name="lightswitchroot1">
                <inertial pos="0 0 0" mass=".1" diaginertia="0.001 0.001 0.001"/>
                <joint axis="1 0 0" limited="true" name="lightswitchroot1:joint" frictionloss="1" range="-.7 .7"/>
                <geom pos="0 0 0.06" euler="0 0 0" size="0.02 0.035" type="capsule" condim="3" contype="0"/>
            </body>
        </body>

        <body name="lightswitchbase2" pos="0.0 0.0 0.41">
			<site name="lightswitchbase2" pos="0 0 0" size="0.01 0.01 0.01" rgba="1 0 0 1" type="sphere"></site>
            <geom mesh="lightswitchbase" pos="0 0 0" euler="0 0 0" condim="3" contype="0"/>
            <body name="lightswitchroot2">
                <inertial pos="0 0 0" mass=".1" diaginertia="0.001 0.001 0.001"/>
                <joint axis="1 0 0" limited="true" name="lightswitchroot2:joint" frictionloss="1" range="-.7 .7"/>
                <geom pos="0 0 0.06" euler="0 0 0" size="0.02 0.035" type="capsule" condim="3" contype="0"/>
            </body>
        </body>

		<include file="robot.xml"></include>

		<body pos="1.3 0.75 0.2" name="table0">
			<geom size="0.25 0.35 0.2" type="box" mass="2000" material="table_mat"></geom>
		</body>
		
		<body name="object0" pos="0.025 0.025 0.025">
			<joint name="object0:joint" type="free" damping="0.01"></joint>
			<geom size="0.025 0.025 0.025" type="box" condim="3" name="object0" material="block_mat1" mass="2"></geom>
			<site name="object0" pos="0 0 0" size="0.02 0.02 0.02" rgba="1 0 0 1" type="sphere"></site>
		</body>
		<body name="object1" pos="0.025 0.025 0.025">
			<joint name="object1:joint" type="free" damping="0.01"></joint>
			<geom size="0.025 0.025 0.025" type="box" condim="3" name="object1" material="block_mat2" mass="2"></geom>
			<site name="object1" pos="0 0 0" size="0.02 0.02 0.02" rgba="0 1 0 1" type="sphere"></site>
		</body>
		<body name="object2" pos="0.025 0.025 0.025">
			<joint name="object2:joint" type="free" damping="0.01"></joint>
			<geom size="0.025 0.025 0.025" type="box" condim="3" name="object2" material="block_mat3" mass="2"></geom>
			<site name="object2" pos="0 0 0" size="0.02 0.02 0.02" rgba="0 1 0 1" type="sphere"></site>
		</body>
		<light directional="true" ambient="0.2 0.2 0.2" diffuse="0.8 0.8 0.8" specular="0.3 0.3 0.3" castshadow="false" pos="0 0 4" dir="0 0 -1" name="light0"></light>
	</worldbody>
	
	<actuator></actuator>
</mujoco>
