<?xml version="1.0" encoding="utf-8"?>
<mujoco>
	<compiler angle="radian" coordinate="local" meshdir="../stls/fetch" texturedir="../textures"></compiler>

    <asset>
        <mesh file="../switch/lightswitch.stl" name="lightswitch"/>
        <mesh file="../switch/lightswitchbase.stl" name="lightswitchbase"/>
    </asset>

	<option timestep="0.002">
		<flag warmstart="enable"></flag>
	</option>

	<include file="shared.xml"></include>
	
	<worldbody>
		<geom name="floor0" pos="0.8 0.75 0" size="0.85 0.70 1" type="plane" condim="3" material="floor_mat"></geom>
		<body name="floor0" pos="0.8 0.75 0">
		</body>

        <body name="lightswitchbase0" pos="0.0 0.0 0.41">
			<site name="lightswitchbase0" pos="0 0 0" size="0.01 0.01 0.01" rgba="1 0 0 1" type="sphere"></site>
            <geom mesh="lightswitchbase" pos="0 0 0" euler="0 0 0" condim="3" contype="0"/>
            <body name="lightswitchroot">
                <inertial pos="0 0 0" mass=".1" diaginertia="0.001 0.001 0.001"/>
                <joint axis="1 0 0" limited="true" name="lightswitchroot0:joint" frictionloss="1" range="-.7 .7"/>
                <geom pos="0 0 0.06" euler="0 0 0" size="0.02 0.035" type="capsule" condim="3" contype="0"/>
            </body>
        </body>

		<include file="robot.xml"></include>

		<body pos="1.3 0.75 0.2" name="table0">
			<geom size="0.25 0.35 0.2" type="box" mass="2000" material="table_mat"></geom>
		</body>
		
		<light directional="true" ambient="0.2 0.2 0.2" diffuse="0.8 0.8 0.8" specular="0.3 0.3 0.3" castshadow="false" pos="0 0 4" dir="0 0 -1" name="light0"></light>
	</worldbody>
	
	<actuator></actuator>
</mujoco>